Workbook

Sheet Dashboard
A1: BoldSign Link Authority Plan 2026
A2: Prepared August 17, 2026. Owner: Nihal Mohamed Ali. Reviewer: Meikandan. Companion to the v2 patch document.
A3: How to use this workbook
A4: - Every tab is a standalone table. Fill yellow cells only. Yellow means you supply the value.
A5: - Workstream A is coverage. Workstream B is authority. Both run in parallel from week 1.
A6: - The status counts below update automatically as you change the Status column on the Tracker tab.
A7: - The three dropped items (Scribd, Issuu, AppSumo) stay in the Tracker marked Dropped so nobody re-adds them.
A8: - No em dashes anywhere by request. Colours follow the BoldSign brand palette.
A10: Live status rollup
A11: Status | B11: Count | C11: Stream A count | D11: Stream B count
A12: Not started | B12: =COUNTIF(Tracker!$F:$F,A12) -> 46 | C12: =COUNTIFS(Tracker!$F:$F,A12,Tracker!$B:$B,"A") -> 34 | D12: =COUNTIFS(Tracker!$F:$F,A12,Tracker!$B:$B,"B") -> 12
A13: Submitted | B13: =COUNTIF(Tracker!$F:$F,A13) -> 0 | C13: =COUNTIFS(Tracker!$F:$F,A13,Tracker!$B:$B,"A") -> 0 | D13: =COUNTIFS(Tracker!$F:$F,A13,Tracker!$B:$B,"B") -> 0
A14: Live | B14: =COUNTIF(Tracker!$F:$F,A14) -> 0 | C14: =COUNTIFS(Tracker!$F:$F,A14,Tracker!$B:$B,"A") -> 0 | D14: =COUNTIFS(Tracker!$F:$F,A14,Tracker!$B:$B,"B") -> 0
A15: Needs review | B15: =COUNTIF(Tracker!$F:$F,A15) -> 0 | C15: =COUNTIFS(Tracker!$F:$F,A15,Tracker!$B:$B,"A") -> 0 | D15: =COUNTIFS(Tracker!$F:$F,A15,Tracker!$B:$B,"B") -> 0
A16: Rejected | B16: =COUNTIF(Tracker!$F:$F,A16) -> 0 | C16: =COUNTIFS(Tracker!$F:$F,A16,Tracker!$B:$B,"A") -> 0 | D16: =COUNTIFS(Tracker!$F:$F,A16,Tracker!$B:$B,"B") -> 0
A17: Dropped | B17: =COUNTIF(Tracker!$F:$F,A17) -> 3 | C17: =COUNTIFS(Tracker!$F:$F,A17,Tracker!$B:$B,"A") -> 3 | D17: =COUNTIFS(Tracker!$F:$F,A17,Tracker!$B:$B,"B") -> 0
A18: Total tracked | B18: =SUM(B12:B17) -> 49 | C18: =SUM(C12:C17) -> 37 | D18: =SUM(D12:D17) -> 12
A20: Tab guide
A21: Tab | B21: What it is | C21: Action needed
A22: Findings | B22: The 17 issues found in the two source files | D22: Read first
A23: Tracker | B23: All 49 rows: 46 active plus 3 dropped, pre-populated | D23: Fill Status, Owner, dates, URLs as you go
A24: Baseline and KPIs | B24: Metrics to prove the programme worked | D24: Fill baseline column before week 1
A25: Competitor Gap | B25: Referring domain gap vs competitors | D25: Fill after Semrush units are restored
A26: Claims Control | B26: Version control for pasted facts | D26: Fill owner and review dates
A27: Bio Library | B27: Six distinct bios and where each goes | D27: Copy exact, do not blend angles
A28: Priority Order | B28: Revised sequence, both streams | D28: Follow top to bottom
A29: Schedule | B29: Honest capacity model and review gates | D29: Adjust dates, not the sequence
A30: UTM Convention | B30: Exact tracking pattern and examples | D30: Build the GA4 filter before week 1
A31: Do Not Do | B31: 14 non-negotiable prohibitions | D31: Read before any outreach

Sheet Findings
A1: Findings: what needs to improve
A2: 17 issues across both source files, highest severity first.
A3: # | B3: Issue | C3: Severity | D3: Where
A4: 1 | B4: Two files share the same H1 and roughly 95 percent identical body. The Guide is a superset of the DA-Action-Plan file. Version drift risk. | C4: High | D4: Both files
A5: 2 | B5: Titled a Domain Authority plan, but around 20 of 28 actions are nofollow or UGC surfaces. Almost nothing passes link equity. | C5: High | D5: Whole plan
A6: 3 | B6: No baseline, no KPI, no success criteria. Cannot prove the programme worked. | C6: High | D6: Goal block
A7: 4 | B7: No referring domain gap analysis against competitors. The plan benchmarks profile presence, never link sources. | C7: High | D7: Missing
A8: 5 | B8: Syncfusion.com and subdomains still in the disavow file. The single highest value zero cost authority action, and it is absent. | C8: High | D8: Missing
A9: 6 | B9: No earned or editorial link workstream at all. No digital PR, no unlinked mention reclamation, no broken link building, no linkable data assets. | C9: High | D9: Missing
A10: 7 | B10: Hardcoded facts pasted into 28 profiles with no version control. Gartner Digital Markets penalises pricing inaccuracy. | C10: Medium | D10: Assets block
A11: 8 | B11: 20 paste-ready bios are the same 8 phrases reshuffled. Reads as boilerplate to directories and to language models. | C11: Medium | D11: All 28 actions
A12: 9 | B12: Eversign and XodoSign listed as separate competitors. Same product post rebrand. Xome and Maverick still unflagged as notary services. | C12: Medium | D12: Competitor block
A13: 10 | B13: SlideShare, Scribd, Issuu sit at priority 5, 6, 7. Near zero value in 2026, all nofollow, same PDF three times. | C13: Medium | D13: Phase 1
A14: 11 | B14: Google Workspace Marketplace ranked 26 of 28, despite being the confirmed highest priority marketplace gap. Weeks of lead time means it must start now. | C14: Medium | D14: Priority table
A15: 12 | B15: No anchor text plan, no target URL distribution. Everything points at homepage or pricing. | C15: Medium | D15: Missing
... A20: 17 | B20: Verified URL section has no re-verification date or cadence. | C20: Low | D20: Guide only

Sheet Tracker
A1: Master tracker: 46 actions plus 3 dropped
A2: Fill yellow columns as you execute. Status drives the Dashboard rollup. Dropped rows stay for the record.
A3: Action ID | B3: Stream | C3: Platform / Action | D3: Difficulty | E3: Priority | F3: Status | G3: Owner | H3: Target Date | I3: Live URL | J3: Login Owner | K3: Category Used | L3: Bio Angle Used | M3: Competitors Benchmarked | N3: Link Type Verified | O3: Review Count | P3: UTM Content Tag | Q3: Date Submitted | R3: Date Live | S3: Next Action | T3: Notes
A4: A00 | B4: B | C4: Syncfusion disavow removal and cross-links | D4: Very easy | E4: 0 | F4: Not started | L4: n/a | M4: n/a | N4: do-follow | P4: a00 | S4: Remove syncfusion.com from disavow then re-audit all entries | T4: Highest value item in the plan. Zero cost.
A5: B01 | B5: B | C5: Referring domain gap analysis | D5: Easy | E5: 1 | F5: Not started | L5: n/a | M5: Tier 1 all | N5: n/a | P5: b01 | S5: Run Semrush Backlink Gap vs 5 competitors | T5: Needs API units allocated first
A6: B02 | B6: B | C6: Unlinked brand mention reclamation | D6: Easy | E6: 2 | F6: Not started | L6: n/a | M6: n/a | N6: varies | P6: b02 | S6: Set up brand monitoring alerts | T6: Weekly 1 hour ongoing
A7: A01 | B7: A | C7: AlternativeTo | D7: Very easy | E7: 3 | F7: Not started | I7: https://alternativeto.net/software/boldsign/ | K7: Electronic Signature, Document Signing, Contract Management, PDF Signing, SaaS | L7: Angle 1 cost | M7: DocuSign, PandaDoc, SignWell, DocHub, DottedSign | N7: nofollow | P7: a01 | S7: Claim listing and map alternatives | T7: Check Inkless presence first
A8: A11 | B8: A | C8: G2 optimisation and review campaign | D8: Easy | E8: 4 | F8: Not started | I8: https://www.g2.com/products/boldsign/reviews | K8: Electronic Signature, Digital Signature | L8: n/a review surface | M8: DocuSign, PandaDoc, SignNow, Dropbox Sign, Zoho Sign, Adobe, Inkless | N8: nofollow | O8: 278 | P8: a11 | S8: Merge weak duplicate API listing then launch review push | T8: Do not paste review count into static copy
A9: A12a | B9: A | C9: Capterra | D9: Easy | E9: 5 | F9: Not started | K9: Electronic Signature, Document Management, Contract Management | L9: Angle 5 SMB | M9: DocuSign, PandaDoc, SignNow, Signeasy | N9: nofollow | P9: a12a | S9: Claim vendor profile | T9: Gartner Digital Markets requires pricing accuracy
A10: A12b | B10: A | C10: GetApp | D10: Easy | E10: 5 | F10: Not started | K10: Electronic Signature, Document Management | L10: Angle 5 SMB | M10: DocuSign, PandaDoc, SignNow | N10: nofollow | P10: a12b | S10: Claim vendor profile | T10: Sync facts with Capterra but vary wording
A11: A12c | B11: A | C11: Software Advice | D11: Easy | E11: 5 | F11: Not started | K11: Electronic Signature, Document Management | L11: Angle 5 SMB | M11: DocuSign, PandaDoc, SignNow | N11: nofollow | P11: a12c | S11: Claim vendor profile
A12: A29a | B12: A | C12: NuGet package pages | D12: Very easy | E12: 6 | F12: Not started | K12: .NET SDK | L12: Angle 3 developer | M12: DocuSign, Dropbox Sign | N12: nofollow | P12: a29a | S12: Populate project URL docs URL and repo fields | T12: Syncfusion .NET audience already here
A13: A29b | B13: A | C13: npm package pages | D13: Very easy | E13: 6 | F13: Not started | K13: Node SDK | L13: Angle 3 developer | M13: DocuSign, Dropbox Sign | N13: nofollow | P13: a29b | S13: Populate homepage repository keywords
A14: A29c | B14: A | C14: PyPI package pages | D14: Very easy | E14: 6 | F14: Not started | K14: Python SDK | L14: Angle 3 developer | M14: DocuSign | N14: nofollow | P14: a29c | S14: Populate Project URLs block
A15: A29d | B15: A | C15: Maven Central | D15: Very easy | E15: 6 | F15: Not started | K15: Java SDK | L15: Angle 3 developer | M15: DocuSign | N15: nofollow | P15: a29d | S15: Populate POM url and scm
A16: A29e | B16: A | C16: Packagist | D16: Very easy | E16: 6 | F16: Not started | K16: PHP SDK | L16: Angle 3 developer | M16: DocuSign | N16: nofollow | P16: a29e | S16: Populate composer.json homepage
A17: A14 | B17: A | C17: GitHub org and repo optimisation | D17: Easy | E17: 7 | F17: Not started | I17: https://github.com/boldsign | K17: Developer | L17: Angle 3 developer | M17: DocuSign org, DocuSign OpenAPI specs | N17: nofollow | P17: a14 | S17: Pin MCP and SDK repos add topics
A18: B05 | B18: B | C18: Free tool roundup outreach | D18: Easy-medium | E18: 8 | F18: Not started | L18: n/a | M18: n/a | N18: do-follow target | P18: b05 | S18: Build roundup target list per tool | T18: Prioritise no-signup tools
A19: A02 | B19: A | C19: SourceForge | D19: Very easy | E19: 9 | F19: Not started | K19: Electronic Signature, Document Management, Contract Management, Workflow Management | L19: Angle 5 SMB | M19: DocuSign, PandaDoc, Zoho Sign | N19: partial do-follow | P19: a02 | S19: Create vendor account and submit
A20: A03 | B20: A | C20: Slashdot | D20: Very easy | E20: 10 | F20: Not started | K20: Same as SourceForge | L20: Angle 1 cost | M20: DocuSign, PandaDoc, SignNow | N20: mirrors SourceForge | P20: a03 | S20: Reuse SourceForge assets vary copy
A21: A04 | B21: A | C21: SaaSHub | D21: Very easy | E21: 11 | F21: Not started | K21: eSignature, Document Management, Contract Management, Legal Tech | L21: Angle 1 cost | M21: PandaDoc, DocuSign, Dropbox Sign, SignNow, Adobe | N21: nofollow | P21: a04 | S21: Claim or submit then add to alternative pages
A22: A08 | B22: A | C22: Crunchbase | D22: Easy | E22: 12 | F22: Not started | K22: Electronic Signature, SaaS, Document Management, Developer APIs | L22: Angle 5 SMB | M22: DocuSign, PandaDoc, SignNow | N22: nofollow | P22: a08 | S22: Create as Syncfusion product entity | T22: Link parent org
A23: A09 | B23: A | C23: LinkedIn showcase and Products tab | D23: Easy | E23: 13 | F23: Not started | I23: https://www.linkedin.com/showcase/bold-sign-app | K23: Software Development | L23: Angle 2 compliance | M23: DocuSign, PandaDoc, OneSpan | N23: nofollow | P23: a09 | S23: Update tagline about and parent company link | T23: Products tab is separate from showcase
A24: B06 | B24: B | C24: Broken link building on rebrand wave | D24: Medium | E24: 14 | F24: Not started | L24: n/a | M24: HelloSign, Eversign, SignRequest, EchoSign | N24: do-follow target | P24: b06 | S24: Run dead URL analysis on rebranded domains | T24: Highest conversion outreach angle
A25: B07 | B25: B | C25: Journalist response programme | D25: Easy | E25: 15 | F25: Not started | L25: n/a | M25: n/a | N25: do-follow target | P25: b07 | S25: Set up Featured Qwoted SourceBottle alerts | T25: Needs named spokesperson
A26: A31 | B26: A | C26: MCP registries expanded | D26: Easy-medium | E26: 16 | F26: Not started | K26: AI Agents | L26: Angle 6 AI | M26: DocuSign API | N26: mixed | P26: a31 | S26: Verify each registry is live then submit | T26: Cross-check llms.txt MCP config block
A27: A13 | B27: A | C27: TrustRadius | D27: Easy-medium | E27: 17 | F27: Not started | K27: Electronic Signature | L27: Angle 2 compliance | M27: DocuSign, PandaDoc, SignNow | N27: nofollow | P27: a13 | S27: Submit vendor request
A28: A16 | B28: A | C28: Pabbly Connect cross-link | D28: Easy | E28: 18 | F28: Not started | I28: https://www.pabbly.com/connect/integrations/boldsign/ | K28: Integration | L28: Angle 4 workflow | M28: DocuSign, PandaDoc, Zoho Sign | N28: nofollow | P28: a16 | S28: Confirm live then request copy refresh | T28: Already live
A29: B10 | B29: B | C29: Partner co-marketing links | D29: Easy-medium | E29: 19 | F29: Not started | L29: n/a | M29: n/a | N29: do-follow target | P29: b10 | S29: Audit partner pages for existing links | T29: Include Syncfusion partner network
A30: A15 | B30: A | C30: Postman public collection | D30: Medium | E30: 20 | F30: Not started | K30: Developer | L30: Angle 3 developer | M30: DocuSign public workspace, Signeasy API | N30: nofollow | P30: a15 | S30: Create workspace and publish | T30: Submit to API Network
A31: A17 | B31: A | C31: Zapier templates and optimisation | D31: Medium | E31: 21 | F31: Not started | I31: https://zapier.com/apps/boldsign/integrations | K31: Signatures | L31: Angle 4 workflow | M31: DocuSign, SignNow, SignWell, Zoho Sign, XodoSign | N31: nofollow | P31: a17 | S31: Publish 5 Zap templates | T31: Already live
A32: A18 | B32: A | C32: HubSpot Marketplace | D32: Medium | E32: 22 | F32: Not started | K32: CRM | L32: Angle 4 workflow | M32: DocuSign, PandaDoc, Dropbox Sign | N32: nofollow | P32: a18 | S32: Refresh screenshots and use cases | T32: Already live. Pursue certification
A33: A19 | B33: A | C33: Salesforce AppExchange | D33: Medium | E33: 23 | F33: Not started | K33: CRM | L33: Angle 4 workflow | M33: DocuSign, PandaDoc, Adobe | N33: nofollow | P33: a19 | S33: Refresh assets and collect reviews | T33: Already live
A34: A23 | B34: A | C34: AI tool directories | D34: Easy-medium | E34: 24 | F34: Not started | K34: Productivity, Business, Legal, Document Automation, AI Agents | L34: Angle 6 AI | M34: PandaDoc, DocuSign, Jotform | N34: varies | P34: a23 | S34: Submit to Futurepedia Toolify TAAFT
A35: A33 | B35: A | C35: Second-tier directories | D35: Easy | E35: 25 | F35: Not started | K35: Electronic Signature | L35: Angle 5 SMB | M35: Tier 1 | N35: varies | P35: a33 | S35: Verify free listing before spending time | T35: Tekpon SaaSworthy GoodFirms Crozdesk Trustpilot Gartner Peer Insights
A36: B03 | B36: B | C36: Legality reference build out | D36: Medium | E36: 26 | F36: Not started | I36: https://www.boldsign.com/electronic-signature-legality/ | L36: n/a | M36: n/a | N36: do-follow target | P36: b03 | S36: Add per-jurisdiction detail and last reviewed dates | T36: CollectionPage schema already live
A37: B04 | B37: B | C37: eSignature statistics page | D37: Medium | E37: 27 | F37: Not started | L37: n/a | M37: n/a | N37: do-follow target | P37: b04 | S37: Source every figure and add original data | T37: Highest yield passive format
A38: B11 | B38: B | C38: Developer content and canonicals | D38: Easy-medium | E38: 28 | F38: Not started | L38: Angle 3 developer | M38: n/a | N38: varies | P38: b11 | S38: Stack Overflow answers and Dev.to with canonical
A39: A10 | B39: A | C39: Wikidata via Syncfusion item | D39: Medium | E39: 29 | F39: Not started | L39: Neutral description | M39: DocuSign Q5287613 | N39: n/a | P39: a10 | S39: Add BoldSign as product statement on Syncfusion item first | T39: Do not create standalone item without secondary sources
A40: A05 | B40: A | C40: SlideShare once only | D40: Very easy | E40: 30 | F40: Not started | L40: Angle 1 cost | M40: DocuSign, Adobe, PandaDoc | N40: nofollow | P40: a05 | S40: Upload one genuinely useful deck | T40: Demoted from priority 5
...

Sheet Baseline and KPIs
A1: Baseline metrics and success criteria
A2: Fill the yellow baseline column before week 1, then re-measure at day 30, 60, 90.
A3: Metric | B3: Baseline | C3: Day 30 | D3: Day 60 | E3: Day 90 | F3: Source
A4: EXAMPLE ROW, delete: Referring domains (root) | B4: 412 | C4: 428 | D4: 445 | E4: 470 | F4: Semrush
A5: Referring domains (root) | F5: Semrush / Ahrefs
A6: Do-follow referring domains | F6: Semrush / Ahrefs
A7: Authority Score | F7: Semrush
A8: Referring domains gained, trailing 90d | F8: Semrush
A9: Referring domains lost, trailing 90d | F9: Semrush
A10: Branded impressions, trailing 28d | F10: GSC
A11: Referral sessions from listing surfaces | F11: GA4
A12: G2 review count | F12: G2 dashboard
A13: Capterra review count | F13: Capterra dashboard
A14: Live directory and marketplace profiles | F14: This tracker
A15: Unlinked brand mentions outstanding | F15: Semrush / Google alerts
A17: Success criteria at day 90
A18: 1. Workstream A: 25 or more live profiles, all facts accurate, all logged in the tracker.
A19: 2. Workstream B: 15 or more new do-follow referring domains from editorial or partner sources.
A20: 3. Review surfaces: G2 plus 15 net new reviews, Capterra plus 10 net new reviews.
A21: 4. Zero inaccurate pricing or compliance claims on any live profile.
A22: 5. Syncfusion cross-link path restored and verified in GSC.

Sheet Competitor Gap
A1: Competitor referring domain gap
A2: Fill after Semrush API units are restored. This decides Workstream B priority order.
A3: Domain | B3: Referring domains | C3: Authority Score | D3: Gap vs BoldSign
A4: boldsign.com | D4: baseline
A5: docusign.com
A6: pandadoc.com
A7: signnow.com
A8: signwell.com
A9: dropbox.com/sign
A10: zoho.com/sign
A12: Note: Semrush returned no data during preparation because this account is out of API units. Ask the account owner to allocate more before running the gap analysis.

Sheet Claims Control
A1: Claims control: version the pasted facts
A2: When one number changes, every profile carrying it goes stale. Own the change here.
A3: Claim | B3: Current value | C3: Verified on | D3: Owner | E3: Next review | F3: Used on (profiles)
A4: Business plan price | B4: from $15/user/month
A5: Free plan allowance | B5: 25 envelopes/month
A6: Unlimited envelopes claim | B6: Business plan and above
A7: Customer count | B7: 50,000+ businesses
A8: Country count | B8: 120+ countries
A9: G2 rating and volume | B9: 4.7 from 278 reviews
A10: G2 badges | B10: Six Leader badges, 2026
A11: Compliance set | B11: SOC 2 Type II, HIPAA, GDPR, PCI DSS, eIDAS, ESIGN, UETA
A12: Data residency | B12: US, EU, CA, AU
A14: Rules
A15: 1. Never paste a review count or star rating into a static third-party description.
A16: 2. Never state a competitor price on a profile you control.
A17: 3. Trusted-by and country counts must trace to a legal-approved source.
A18: 4. When any row changes, the owner sweeps every profile in Used on within 14 days.
A19: 5. Prefer from $15/user/month over $15/user/month so the claim survives plan changes.

Sheet Bio Library
A1: Bio library: six angles, no overlap
A2: Copy exact. Never run the same angle on two competing surfaces in one category.
A3: Angle and where to use | B3: Long form, paste exact | C3: Short form, 160 characters or under
A4: Angle 1 Cost and volume Use on AlternativeTo, SaaSHub, Slashdot, deal and comparison surfaces | B4: Most eSignature tools charge per envelope, so costs climb the moment a team starts sending real volume. BoldSign removes that ceiling: the Business plan includes unlimited envelopes from $15 per user per month, and a free plan covers low-volume teams. Built by Syncfusion, it handles sending, signing, tracking, templates, and audit trails without volume penalties. | C4: eSignature software with unlimited envelopes from $15 per user per month, plus a free plan. Built by Syncfusion.
A5: Angle 2 Compliance and security Use on TrustRadius, Gartner Peer Insights, enterprise and legal surfaces | B5: BoldSign is an electronic signature platform built for teams that have to defend a signed document later. Every envelope carries a tamper-evident audit trail, signer authentication options, and AES-256 encryption at rest. The platform supports SOC 2 Type II, HIPAA, GDPR, PCI DSS, ESIGN, UETA, and eIDAS requirements, with data residency in the US, EU, Canada, and Australia. | C5: Secure eSignatures with tamper-evident audit trails, signer authentication, and SOC 2 Type II, HIPAA, GDPR, and eIDAS support.
A6: Angle 3 Developer and API Use on GitHub, Postman, package registries, RapidAPI, developer directories | B6: BoldSign gives developers a REST API, official SDKs, webhooks, and embedded signing so signature workflows live inside the product rather than beside it. Create documents from templates, drop signing into your own UI, and react to signing events in real time. A free sandbox is available for integration work before you commit to a plan. | C6: eSignature APIs, SDKs, webhooks, and embedded signing with a free developer sandbox.
A7: Angle 4 CRM and operations workflow Use on HubSpot, Salesforce, Zapier, Make, n8n, Pabbly, Workspace, AppSource, Slack | B7: BoldSign connects signature requests to the systems your team already works in. Trigger a document from a closed-won deal, a submitted form, or an approved quote, then push status back so nobody chases a signature manually. Sales, HR, and operations teams use it for contracts, offer letters, NDAs, and onboarding paperwork. | C7: Send, track, and manage signature requests from your CRM, forms, and automation tools.
A8: Angle 5 SMB and ease of use Use on Capterra, GetApp, Software Advice, SourceForge, Trustpilot, Product Hunt | B8: Small teams do not need an enterprise rollout to start signing documents. BoldSign lets you upload a document, place fields, and send it for signature in minutes, then reuse it as a template. A free plan covers occasional signing, and paid plans lift the volume cap without per-envelope charges. | C8: Upload, place fields, send. Reusable templates and a free plan for low-volume signing.
A9: Angle 6 AI and agents Use on MCP registries, Futurepedia, Toolify, TAAFT, AI directories | B9: BoldSign exposes its signature workflows through an MCP server, so AI assistants and agent frameworks can send documents, check signing status, and manage templates as tool calls. Teams building agentic workflows can put a legally binding signature step inside an automated process rather than breaking out to a human handoff. | C9: An MCP server that lets AI assistants send, track, and manage legally binding signature requests.

Sheet Priority Order
A1: Revised priority order
A2: Workstream A is coverage. Workstream B is authority. Run both in parallel.
A3: Order | B3: Action | C3: Stream | D3: Difficulty | E3: Speed | F3: Real value
A4: 0 | B4: Syncfusion disavow fix and cross-links | C4: B | D4: Very easy | E4: Same day | F4: Recovers existing authority
A5: 1 | B5: B1 referring domain gap analysis | C5: B | D5: Easy | E5: Same day | F5: Determines all outreach
A6: 2 | B6: B2 unlinked mention reclamation | C6: B | D6: Easy | E6: Ongoing | F6: Do-follow, fastest wins
A7: 3 | B7: AlternativeTo | C7: A | D7: Very easy | E7: Same day | F7: Alternative discovery
A8: 4 | B8: G2 optimisation and review campaign | C8: A | D8: Easy | E8: Ongoing | F8: Review trust, comparison visibility
A9: 5 | B9: Capterra, GetApp, Software Advice | C9: A | D9: Easy | E9: 1 day | F9: High-intent buyer referral
A10: 6 | B10: Package registry cleanup, action 29 | C10: A | D10: Very easy | E10: 2 hours | F10: Developer discovery
A11: 7 | B11: GitHub org and repo optimisation | C11: A | D11: Easy | E11: Same day | F11: Developer, LLM visibility
A12: 8 | B12: B5 free tool roundup outreach | C12: B | D12: Easy-medium | E12: 1 week | F12: Do-follow
A13: 9 | B13: SourceForge | C13: A | D13: Very easy | E13: Same day | F13: Directory backlink
A14: 10 | B14: Slashdot | C14: A | D14: Very easy | E14: Same day | F14: Directory backlink
A15: 11 | B15: SaaSHub | C15: A | D15: Very easy | E15: Same day | F15: Alternative pages
... A41: 37 | B41: B9 original research | C41: B | D41: Difficult | E41: 6 to 10 weeks | F41: Highest link yield
A43: Parallel track, own milestone dates, not in the sequence above
A44: Track | B44: Action | C44: Start | D44: Target live
A45: P1 | B45: Google Workspace Marketplace | C45: Week 1 scoping | D45: Month 3
A46: P2 | B46: Microsoft AppSource and Teams | C46: Week 2 scoping | D46: Month 3 to 4
A48: Dropped: Scribd, Issuu, AppSumo. See the patch document demote list for reasoning.

Sheet Schedule
A1: Execution schedule and capacity
A2: Honest total is 70 to 90 hours plus ongoing outreach. At 8 hours a week this is a 5 to 6 month plan.
A3: Week | B3: Focus | C3: Actions | D3: Hours | E3: Owner
A4: 1 | B4: Foundation and fastest wins | C4: Action 0, B1, baseline capture, AlternativeTo, package registries | D4: 8
A5: 1 | B5: Parallel kickoff | C5: P1 Workspace scoping conversation | D5: 1
A6: 2 | B6: Review surfaces | C6: G2 optimisation, Capterra, GetApp, Software Advice, review campaign launch | D6: 8
A7: 3 | B7: Directories and entity | C7: SourceForge, Slashdot, SaaSHub, Crunchbase, LinkedIn | D7: 7
A8: 4 | B8: Developer and AI | C8: GitHub, MCP registries, Postman, AI directories | D8: 8
A9: 5 | B9: Outreach engine on | C9: B2 mention reclamation, B5 free tool roundups, B7 alerts live | D9: 8
A10: 6 | B10: Integration marketplaces | C10: Pabbly, Zapier templates, HubSpot, Salesforce | D10: 8
A11: 7 | B11: Earned links | C11: B6 broken link building, B10 partner links | D11: 8
A12: 8 | B12: Content assets begin | C12: B3 legality reference scope and first tranche | D12: 8
A13: 9 to 12 | B13: Content assets and long tail | C13: B3 completion, B4 statistics page, second-tier directories, TrustRadius | D13: 32
A14: Month 4+ | B14: Builds and research | C14: Slack, WordPress, Make, n8n, B8, B9, Product Hunt | D14: ongoing
A16: Ongoing weekly commitments, separate from the table above
A17: Commitment | B17: Time
A18: B2 mention sweep | B18: 1 hour weekly
A19: B7 journalist responses | B19: 3 hours weekly
A20: Review campaign follow-up | B20: 1 hour weekly
A21: Reddit calendar, existing programme | B21: per existing calendar
A22: Tracker hygiene | B22: 30 minutes weekly
A23: Total maintenance | B23: 5.5 hours weekly, budget before adding new actions
A25: Review gates
A26: Gate | B26: When | C26: Criteria
A27: G1 | B27: End of week 1 | C27: Baseline captured, Action 0 complete, B1 list of 100 exported
A28: G2 | B28: End of week 4 | C28: 12 or more profiles live, all claims verified, zero inaccurate pricing
A29: G3 | B29: End of week 8 | C29: 5 or more new do-follow referring domains from Workstream B
A30: G4 | B30: Day 90 | C30: Full success criteria from the Baseline tab
A32: Escalate to Meikandan at any gate that misses by more than 25 percent.

Sheet UTM Convention
A1: UTM convention
A2: Lowercase, hyphens only, no spaces. Build the GA4 filter before week 1.
A3: Pattern: ?utm_source=[platform-slug]&utm_medium=[medium]&utm_campaign=link-authority-2026&utm_content=[action-id]
A5: Medium | B5: Use for
A6: listing | B6: Directories and software listings
A7: review | B7: G2, Capterra, GetApp, Software Advice, TrustRadius, Trustpilot
A8: marketplace | B8: HubSpot, Salesforce, Workspace, AppSource, Slack, Zapier, Make, n8n, Pabbly
A9: developer | B9: GitHub, Postman, package registries, MCP registries
A10: community | B10: Reddit, forums, Stack Overflow, community replies
A11: earned | B11: Workstream B editorial placements
A13: Examples
A14: https://www.boldsign.com/?utm_source=alternativeto&utm_medium=listing&utm_campaign=link-authority-2026&utm_content=a01
A15: https://developers.boldsign.com/?utm_source=nuget&utm_medium=developer&utm_campaign=link-authority-2026&utm_content=a29
A16: https://www.boldsign.com/free-tools/merge-pdf/?utm_source=[publisher]&utm_medium=earned&utm_campaign=link-authority-2026&utm_content=b05
A18: Rules
A19: 1. Never put a UTM on a link you want to pass equity. Use UTMs on nofollow referral surfaces only.
A20: 2. Never UTM a link inside a Wikidata or Wikipedia reference.
A21: 3. Build a GA4 exploration filtered to utm_campaign=link-authority-2026 before week 1.

Sheet Do Not Do
A1: Do not do: non-negotiable
A2: Anything here creates risk that outweighs any link gained.
A3: # | B3: Prohibition
A4: 1 | B4: No paid links, sponsored do-follow placements, or guest post for a fee arrangements. If a site quotes a price for a link, walk away or require rel=sponsored.
A5: 2 | B5: No link marketplaces, PBNs, or link packages from freelance marketplaces.
A6: 3 | B6: No fake reviews, incentivised reviews outside the platform official programme, employee reviews posing as customers, or competitor review manipulation.
A7: 4 | B7: No fake AlternativeTo likes, no vote manipulation, no sockpuppet accounts on any surface.
A8: 5 | B8: No sitewide footer or nav cross-link between syncfusion.com and boldsign.com. Contextual in-content links only.
A9: 6 | B9: No spun or near-duplicate descriptions across directories. Use the six angles in the Bio Library.
A10: 7 | B10: No exact-match commercial anchor above 3 percent of the acquired profile.
A11: 8 | B11: No undisclosed vendor participation in any community thread. Disclose in the first sentence, every time.
A12: 9 | B12: No stating competitor pricing on any third-party profile you control.
A13: 10 | B13: No compliance claim that is not currently certified and evidenced. SOC 2, HIPAA, and eIDAS claims carry legal exposure.
A14: 11 | B14: No creating a second BoldSign profile on a platform where one already exists. Claim or merge, never duplicate.
A15: 12 | B15: No mass directory submission tools or automated blast services.
... A17: 14 | B17: No lifetime deal or perpetual licence offer on any deal platform.
